Workbook
Name solver_adj: 'Model Summary'!$CP$66
Name solver_lhs1: 'Model Summary'!$CM$65
Name solver_opt: 'Model Summary'!$CM$65

Sheet Fee Table
C2: Wellness Referendum
C3: Fee Table – 30 years
C4: prepared by Hugh G. Graham, Campus Budget Office
C5: ='Model Summary'!B5 -> REVISED DRAFT 2/26/15
E6: Fall/Spring per semester | K6: Summer
C7: Year | E7: current base fees | F7: RSF membership fee | G7: additional fee | H7: total fee | I7: fee in 2015 dollars * | K7: current base fees | L7: RSF membership fee | M7: additional fee | N7: total fee | O7: fee in 2015 dollars *
A8: 0 | C8: 2015-16 | E8: 83.5 | F8: ='Fee Revenue'!E15 -> 8.5 | G8: 54 | H8: ='Fee Revenue'!E20 -> 146 | I8: =PV($G$39,$A8,0,-H8) -> 146 | K8: ='Fee Revenue'!E27 -> 60.5 | L8: ='Fee Revenue'!E29 -> 8.5 | M8: ='Fee Revenue'!E31 -> 41 | N8: ='Fee Revenue'!E33 -> 110 | O8: =PV($G$39,$A8,0,-N8) -> 110
A9: 1 | C9: 2016-17 | E9: ='Fee Revenue'!H12 -> 86.25 | F9: ='Fee Revenue'!H15 -> 8.75 | G9: ='Fee Revenue'!H18 -> 57 | H9: ='Fee Revenue'!H20 -> 152 | I9: =PV($G$39,$A9,0,-H9) -> 147.57282 | K9: same as Fall/Spring
A10: =A9+1 -> 2 | C10: 2017-18 | E10: ='Fee Revenue'!K12 -> 90 | F10: ='Fee Revenue'!K15 -> 9 | G10: ='Fee Revenue'!K18 -> 60 | H10: ='Fee Revenue'!K20 -> 159 | I10: =PV($G$39,$A10,0,-H10) -> 149.87275 | K10: " "
A11: =A10+1 -> 3 | C11: 2018-19 | E11: ='Fee Revenue'!N12 -> 93.75 | F11: ='Fee Revenue'!N15 -> 9.25 | G11: ='Fee Revenue'!N18 -> 64 | H11: ='Fee Revenue'!N20 -> 167 | I11: =PV($G$39,$A11,0,-H11) -> 152.82866 | K11: " "
A12: =A11+1 -> 4 | C12: 2019-20 | E12: ='Fee Revenue'!Q12 -> 97.5 | F12: ='Fee Revenue'!Q15 -> 9.5 | G12: ='Fee Revenue'!Q18 -> 68 | H12: ='Fee Revenue'!Q20 -> 175 | I12: =PV($G$39,$A12,0,-H12) -> 155.48523 | K12: " "
A13: =A12+1 -> 5 | C13: 2020-21 | E13: ='Fee Revenue'!T12 -> 100.25 | F13: ='Fee Revenue'!T15 -> 9.75 | G13: ='Fee Revenue'!T18 -> 72 | H13: ='Fee Revenue'!T20 -> 182 | I13: =PV($G$39,$A13,0,-H13) -> 156.9948 | K13: " "
A14: =A13+1 -> 6 | C14: 2021-22 | E14: ='Fee Revenue'!W12 -> 104 | F14: ='Fee Revenue'!W15 -> 10 | G14: ='Fee Revenue'!W18 -> 76 | H14: ='Fee Revenue'!W20 -> 190 | I14: =PV($G$39,$A14,0,-H14) -> 159.12201 | K14: " "
A15: =A14+1 -> 7 | C15: 2022-23 | E15: ='Fee Revenue'!Z12 -> 107.75 | F15: ='Fee Revenue'!Z15 -> 10.25 | G15: ='Fee Revenue'!Z18 -> 81 | H15: ='Fee Revenue'!Z20 -> 199 | I15: =PV($G$39,$A15,0,-H15) -> 161.80521 | K15: " "
A16: =A15+1 -> 8 | C16: 2023-24 | E16: ='Fee Revenue'!AC12 -> 111.5 | F16: ='Fee Revenue'!AC15 -> 10.5 | G16: ='Fee Revenue'!AC18 -> 86 | H16: ='Fee Revenue'!AC20 -> 208 | I16: =PV($G$39,$A16,0,-H16) -> 164.19712 | K16: " "
A17: =A16+1 -> 9 | C17: 2024-25 | E17: ='Fee Revenue'!AF12 -> 115.25 | F17: ='Fee Revenue'!AF15 -> 10.75 | G17: ='Fee Revenue'!AF18 -> 91 | H17: ='Fee Revenue'!AF20 -> 217 | I17: =PV($G$39,$A17,0,-H17) -> 166.31243 | K17: " "
A18: =A17+1 -> 10 | C18: 2025-26 | E18: ='Fee Revenue'!AI12 -> 120 | F18: ='Fee Revenue'!AI15 -> 11 | G18: ='Fee Revenue'!AI18 -> 97 | H18: ='Fee Revenue'!AI20 -> 228 | I18: =PV($G$39,$A18,0,-H18) -> 169.65341 | K18: " "
A19: =A18+1 -> 11 | C19: 2026-27 | E19: ='Fee Revenue'!AL12 -> 124.75 | F19: ='Fee Revenue'!AL15 -> 11.25 | G19: ='Fee Revenue'!AL18 -> 103 | H19: ='Fee Revenue'!AL20 -> 239 | I19: =PV($G$39,$A19,0,-H19) -> 172.65869 | K19: " "
A20: =A19+1 -> 12 | C20: 2027-28 | E20: ='Fee Revenue'!AO12 -> 128.5 | F20: ='Fee Revenue'!AO15 -> 11.5 | G20: ='Fee Revenue'!AO18 -> 109 | H20: ='Fee Revenue'!AO20 -> 249 | I20: =PV($G$39,$A20,0,-H20) -> 174.64359 | K20: " "
A21: =A20+1 -> 13 | C21: 2028-29 | E21: ='Fee Revenue'!AR12 -> 132.25 | F21: ='Fee Revenue'!AR15 -> 11.75 | G21: ='Fee Revenue'!AR18 -> 116 | H21: ='Fee Revenue'!AR20 -> 260 | I21: =PV($G$39,$A21,0,-H21) -> 177.04735 | K21: " "
A22: =A21+1 -> 14 | C22: 2029-30 | E22: ='Fee Revenue'!AU12 -> 137 | F22: ='Fee Revenue'!AU15 -> 12 | G22: ='Fee Revenue'!AU18 -> 123 | H22: ='Fee Revenue'!AU20 -> 272 | I22: =PV($G$39,$A22,0,-H22) -> 179.82404 | K22: " "
A23: =A22+1 -> 15 | C23: 2030-31 | E23: ='Fee Revenue'!AX12 -> 141.75 | F23: ='Fee Revenue'!AX15 -> 12.25 | G23: ='Fee Revenue'!AX18 -> 130 | H23: ='Fee Revenue'!AX20 -> 284 | I23: =PV($G$39,$A23,0,-H23) -> 182.28879 | K23: " "
A24: =A23+1 -> 16 | C24: 2031-32 | E24: ='Fee Revenue'!BA12 -> 146.5 | F24: ='Fee Revenue'!BA15 -> 12.5 | G24: ='Fee Revenue'!BA18 -> 138 | H24: ='Fee Revenue'!BA20 -> 297 | I24: =PV($G$39,$A24,0,-H24) -> 185.08058 | K24: " "
A25: =A24+1 -> 17 | C25: 2032-33 | E25: ='Fee Revenue'!BD12 -> 152 | F25: ='Fee Revenue'!BD15 -> 13 | G25: ='Fee Revenue'!BD18 -> 146 | H25: ='Fee Revenue'!BD20 -> 311 | I25: =PV($G$39,$A25,0,-H25) -> 188.16011 | K25: " "
A26: =A25+1 -> 18 | C26: 2033-34 | E26: ='Fee Revenue'!BG12 -> 157.5 | F26: ='Fee Revenue'!BG15 -> 13.5 | G26: ='Fee Revenue'!BG18 -> 155 | H26: ='Fee Revenue'!BG20 -> 326 | I26: =PV($G$39,$A26,0,-H26) -> 191.49064 | K26: " "
A27: =A26+1 -> 19 | C27: 2034-35 | E27: ='Fee Revenue'!BJ12 -> 163 | F27: ='Fee Revenue'!BJ15 -> 14 | G27: ='Fee Revenue'!BJ18 -> 164 | H27: ='Fee Revenue'!BJ20 -> 341 | I27: =PV($G$39,$A27,0,-H27) -> 194.46754 | K27: " "
A28: =A27+1 -> 20 | C28: 2035-36 | E28: ='Fee Revenue'!BM12 -> 168.5 | F28: ='Fee Revenue'!BM15 -> 14.5 | G28: ='Fee Revenue'!BM18 -> 174 | H28: ='Fee Revenue'!BM20 -> 357 | I28: =PV($G$39,$A28,0,-H28) -> 197.66224 | K28: " "
A29: =A28+1 -> 21 | C29: 2036-37 | E29: ='Fee Revenue'!BP12 -> 175 | F29: ='Fee Revenue'!BP15 -> 15 | G29: ='Fee Revenue'!BP18 -> 185 | H29: ='Fee Revenue'!BP20 -> 375 | I29: =PV($G$39,$A29,0,-H29) -> 201.58098 | K29: " "
A30: =A29+1 -> 22 | C30: 2037-38 | E30: ='Fee Revenue'!BS12 -> 180.5 | F30: ='Fee Revenue'!BS15 -> 15.5 | G30: ='Fee Revenue'!BS18 -> 196 | H30: ='Fee Revenue'!BS20 -> 392 | I30: =PV($G$39,$A30,0,-H30) -> 204.58186 | K30: " "
A31: =A30+1 -> 23 | C31: 2038-39 | E31: ='Fee Revenue'!BV12 -> 187 | F31: ='Fee Revenue'!BV15 -> 16 | G31: ='Fee Revenue'!BV18 -> 208 | H31: ='Fee Revenue'!BV20 -> 411 | I31: =PV($G$39,$A31,0,-H31) -> 208.25031 | K31: " "
A32: =A31+1 -> 24 | C32: 2039-40 | E32: ='Fee Revenue'!BY12 -> 193.5 | F32: ='Fee Revenue'!BY15 -> 16.5 | G32: ='Fee Revenue'!BY18 -> 221 | H32: ='Fee Revenue'!BY20 -> 431 | I32: =PV($G$39,$A32,0,-H32) -> 212.02344 | K32: " "
A33: =A32+1 -> 25 | C33: 2040-41 | E33: ='Fee Revenue'!CB12 -> 200 | F33: ='Fee Revenue'!CB15 -> 17 | G33: ='Fee Revenue'!CB18 -> 234 | H33: ='Fee Revenue'!CB20 -> 451 | I33: =PV($G$39,$A33,0,-H33) -> 215.40011 | K33: " "
A34: =A33+1 -> 26 | C34: 2041-42 | E34: ='Fee Revenue'!CE12 -> 206.5 | F34: ='Fee Revenue'!CE15 -> 17.5 | G34: ='Fee Revenue'!CE18 -> 248 | H34: ='Fee Revenue'!CE20 -> 472 | I34: =PV($G$39,$A34,0,-H34) -> 218.86391 | K34: " "
A35: =A34+1 -> 27 | C35: 2042-43 | E35: ='Fee Revenue'!CH12 -> 214 | F35: ='Fee Revenue'!CH15 -> 18 | G35: ='Fee Revenue'!CH18 -> 263 | H35: ='Fee Revenue'!CH20 -> 495 | I35: =PV($G$39,$A35,0,-H35) -> 222.84358 | K35: " "
A36: =A35+1 -> 28 | C36: 2043-44 | E36: ='Fee Revenue'!CK12 -> 220.5 | F36: ='Fee Revenue'!CK15 -> 18.5 | G36: ='Fee Revenue'!CK18 -> 279 | H36: ='Fee Revenue'!CK20 -> 518 | I36: =PV($G$39,$A36,0,-H36) -> 226.40576 | K36: " "
A37: =A36+1 -> 29 | C37: 2044-45 | E37: ='Fee Revenue'!CN12 -> 228 | F37: ='Fee Revenue'!CN15 -> 19 | G37: ='Fee Revenue'!CN18 -> 296 | H37: ='Fee Revenue'!CN20 -> 543 | I37: =PV($G$39,$A37,0,-H37) -> 230.42007 | K37: " "
C39: * assumes inflation of: | G39: 0.03

Sheet Fee Breakdown
B2: Wellness Referendum
B3: Fee Breakdown
B4: prepared by Hugh G. Graham, Campus Budget Office
B7: Approximate break-down of gross fee revenue (subject to change) | D7: 2015-16
B9: 1 | C9: Return-to-aid | D9: =-'Model Summary'!F9 -> 0.26604692
C10: (33% for all UC students, 0% non-UC summer students)
B12: 2 | C12: RSF Existing Services & Programs | D12: ='Model Summary'!F38 -> 0.48079816
B14: 3 | C14: UHS extended hours, sexual assault student resources, and improved mental health counseling along with operational, furnishing, and alteration costs to provide such services | D14: ='Model Summary'!F42 -> 0.13360953
B16: 4 | C16: New wellness services including operational, furnishings, and alteration costs to provide such services | D16: ='Model Summary'!F46 -> 0.077352887
B18: 5 | C18: Diversity student wellness programs and associated costs | D18: ='Model Summary'!F50 -> 0.028128322
B20: 6 | C20: Wellness sustainability plan to lower student costs over time | D20: ='Model Summary'!F53 -> 0.0070320806
B22: 7 | C22: Sexual assault prevention and support | D22: ='Model Summary'!F56 -> 0.0070320806
D24: ='Model Summary'!F58 -> 0
B26: TOTAL | D26: =SUM(D9:D25) -> 0.99999999

Sheet New Services - Budget Breakdown
B2: Wellness Referendum
B3: New Services – Budget Breakdown
B4: prepared by Hugh G. Graham, Campus Budget Office
B5: ='Model Summary'!B5 -> REVISED DRAFT 2/26/15
B7: 5a. | C7: UHS extended hours and improved mental health counseling along with operational, furnishing, and alteration costs to provide such services
D10: TOTAL | F10: UHS
D11: $ | F11: % | G11: $
C12: Hours of operation:
C13: 2 evenings until 8pm | D13: 235638 | F13: 1 | G13: =$D13*F13 -> 235638
C14: Sunday | D14: 412376 | F14: 1 | G14: =$D14*F14 -> 412376
C15: Saturday | D15: 111568 | F15: 1 | G15: =$D15*F15 -> 111568
C16: subtotal | D16: =SUM(D13:D15) -> 759582 | F16: 1 | G16: =$D16*F16 -> 759582
C18: counselings in academic bldgs | D18: 0 | F18: 1 | G18: =$D18*F18 -> 0
C20: counselings in primary care | D20: 1023731 | F20: 1 | G20: =$D20*F20 -> 1023731
C22: TOTAL | D22: =SUM(D16:D21) -> 1783313 | F22: 1 | G22: =$D22*F22 -> 1783313
B25: 5b. | C25: New wellness services including operational, furnishings, and alteration costs to provide such services
D27: TOTAL | F27: UHS | I27: RSF
D28: $ | F28: % | G28: $ | I28: % | J28: $
C30: Item X | D30: 0 | F30: 0 | G30: =$D30*F30 -> 0 | I30: 0 | J30: =$D30*I30 -> 0
C32: Item Y | D32: 0 | F32: 0 | G32: =$D32*F32 -> 0 | I32: 0 | J32: =$D32*I32 -> 0
C34: Item Z | D34: 0 | F34: 0 | G34: =$D34*F34 -> 0 | I34: 0 | J34: =$D34*I34 -> 0
C36: TOTAL | D36: =SUM(D30:D35) -> 0 | F36: 1 | G36: =$D36*F36 -> 0 | I36: 0 | J36: =$D36*I36 -> 0
B38: 5c. | C38: Diversity student wellness programs and associated costs
D40: TOTAL | F40: UHS | I40: RSF
D41: $ | F41: % | G41: $ | I41: % | J41: $
C43: Item X | D43: 0 | F43: 0 | G43: =$D43*F43 -> 0 | I43: 0 | J43: =$D43*I43 -> 0
C45: Item Y | D45: 0 | F45: 0 | G45: =$D45*F45 -> 0 | I45: 0 | J45: =$D45*I45 -> 0
C47: Item Z | D47: 0 | F47: 0 | G47: =$D47*F47 -> 0 | I47: 0 | J47: =$D47*I47 -> 0
C49: TOTAL | D49: =SUM(D43:D48) -> 0 | F49: 1 | G49: =$D49*F49 -> 0 | I49: 0 | J49: =$D49*I49 -> 0
B51: 5d. | C51: Wellness sustainability plan to lower student costs over time
D53: TOTAL | F53: UHS | I53: RSF
D54: $ | F54: % | G54: $ | I54: % | J54: $
C56: Item X | D56: 0 | F56: 0 | G56: =$D56*F56 -> 0 | I56: 0 | J56: =$D56*I56 -> 0
C58: Item Y | D58: 0 | F58: 0 | G58: =$D58*F58 -> 0 | I58: 0 | J58: =$D58*I58 -> 0
C60: Item Z | D60: 0 | F60: 0 | G60: =$D60*F60 -> 0 | I60: 0 | J60: =$D60*I60 -> 0
C62: TOTAL | D62: =SUM(D56:D61) -> 0 | F62: 1 | G62: =$D62*F62 -> 0 | I62: 0 | J62: =$D62*I62 -> 0
B64: 5e. | C64: Sexual assault prevention and support
D66: TOTAL | F66: Dean of Students
D67: $ | F67: % | G67: $
C69: Item X | D69: 0 | F69: 1 | G69: =$D69*F69 -> 0
...

Sheet Chart - Surplus (Deficit)
B2: Wellness Referendum Model Surplus (Deficit) Chart – 30 years
B4: prepared by Hugh G. Graham, Campus Budget Office
B5: ='Model Summary'!B5 -> REVISED DRAFT 2/26/15
B7: $ in millions
B8: Surplus (Deficit) | C8: 2015-16 | D8: 2016-17 | E8: 2017-18 | F8: 2018-19 | G8: 2019-20 | H8: 2020-21 | I8: 2021-22 | J8: 2022-23 | K8: 2023-24 | L8: 2024-25 | M8: 2025-26 | N8: 2026-27 | O8: 2027-28 | P8: 2028-29 | Q8: 2029-30 | R8: 2030-31 | S8: 2031-32 | T8: 2032-33 | U8: 2033-34 | V8: 2034-35 | W8: 2035-36 | X8: 2036-37 | Y8: 2037-38 | Z8: 2038-39 | AA8: 2039-40 | AB8: 2040-41 | AC8: 2041-42 | AD8: 2042-43 | AE8: 2043-44 | AF8: 2044-45 | AG8: TOTAL
B9: RSF Existing Services | C9: ='Model Summary'!D64 -> 0.15666667 | D9: ='Model Summary'!G64 -> 0 | E9: ='Model Summary'!J64 -> 0 | F9: ='Model Summary'!M64 -> 0 | G9: ='Model Summary'!P64 -> 0 | H9: ='Model Summary'!S64 -> 0 | I9: ='Model Summary'!V64 -> 0 | J9: ='Model Summary'!Y64 -> 0 | K9: ='Model Summary'!AB64 -> 0 | L9: ='Model Summary'!AE64 -> 0 | M9: ='Model Summary'!AH64 -> 0 | N9: ='Model Summary'!AK64 -> 0 | O9: ='Model Summary'!AN64 -> 0 | P9: ='Model Summary'!AQ64 -> 0 | Q9: ='Model Summary'!AT64 -> 0 | R9: ='Model Summary'!AW64 -> 0 | S9: ='Model Summary'!AZ64 -> 0 | T9: ='Model Summary'!BC64 -> 0 | U9: ='Model Summary'!BF64 -> 0 | V9: ='Model Summary'!BI64 -> 0 | W9: ='Model Summary'!BL64 -> 0 | X9: ='Model Summary'!BO64 -> 0 | Y9: ='Model Summary'!BR64 -> 0 | Z9: ='Model Summary'!BU64 -> 0 | AA9: ='Model Summary'!BX64 -> 0 | AB9: ='Model Summary'!CA64 -> 0 | AC9: ='Model Summary'!CD64 -> 0 | AD9: ='Model Summary'!CG64 -> 0 | AE9: ='Model Summary'!CJ64 -> 0 | AF9: ='Model Summary'!CM64 -> 0 | AG9: =SUM(C9:AF9) -> 0.15666667
B10: New Services | C10: ='Model Summary'!D65 -> 0 | D10: ='Model Summary'!G65 -> -6867.7778 | E10: ='Model Summary'!J65 -> -24783.9 | F10: ='Model Summary'!M65 -> 5848.7546 | G10: ='Model Summary'!P65 -> 23910.221 | H10: ='Model Summary'!S65 -> 28559.951 | I10: ='Model Summary'!V65 -> 18899.743 | J10: ='Model Summary'!Y65 -> 54303.072 | K10: ='Model Summary'!AB65 -> 73410.811 | L10: ='Model Summary'!AE65 -> 62793.32 | M10: ='Model Summary'!AH65 -> 106278.88 | N10: ='Model Summary'!AK65 -> 117615.14 | O10: ='Model Summary'!AN65 -> 120130.13 | P10: ='Model Summary'!AQ65 -> 148059.67 | Q10: ='Model Summary'!AT65 -> 151874.22 | R10: ='Model Summary'!AW65 -> 142272.06 | S10: ='Model Summary'!AZ65 -> 153171.96 | T10: ='Model Summary'!BC65 -> 134705.27 | U10: ='Model Summary'!BF65 -> 132874.25 | V10: ='Model Summary'!BI65 -> 109876.39 | W10: ='Model Summary'!BL65 -> 111428.1 | X10: ='Model Summary'!BO65 -> 122754.47 | Y10: ='Model Summary'!BR65 -> 93244.918 | Z10: ='Model Summary'!BU65 -> 80441.391 | AA10: ='Model Summary'!BX65 -> 81359.13 | AB10: ='Model Summary'!CA65 -> 32473.183 | AC10: ='Model Summary'!CD65 -> -21629.346 | AD10: ='Model Summary'!CG65 -> -72264.722 | AE10: ='Model Summary'!CJ65 -> -123335.75 | AF10: ='Model Summary'!CM65 -> -179016.08 | AG10: =SUM(C10:AF10) -> 1678387.5
B11: COMBINED | C11: =SUM(C9:C10) -> 0.15666667 | D11: =SUM(D9:D10) -> -6867.7778 | E11: =SUM(E9:E10) -> -24783.9 | F11: =SUM(F9:F10) -> 5848.7546 | G11: =SUM(G9:G10) -> 23910.221 | H11: =SUM(H9:H10) -> 28559.951 | I11: =SUM(I9:I10) -> 18899.743 | J11: =SUM(J9:J10) -> 54303.072 | ... AF11: =SUM(AF9:AF10) -> -179016.08 | AG11: =SUM(C11:AF11) -> 1678387.6

Sheet Chart - Fee Breakdown
B2: Wellness Referendum Model Fee $'s Per Year Breakdown – 30 years
B4: prepared by Hugh G. Graham, Campus Budget Office
B5: ='Model Summary'!B5 -> REVISED DRAFT 2/26/15
B7: $ in millions
B8: Breakdown of Fee $'s Per Year | C8: 2015-16 | D8: 2016-17 | E8: 2017-18 | F8: 2018-19 | G8: 2019-20 | H8: 2020-21 | I8: 2021-22 | J8: 2022-23 | K8: 2023-24 | L8: 2024-25 | M8: 2025-26 | N8: 2026-27 | O8: 2027-28 | P8: 2028-29 | Q8: 2029-30 | R8: 2030-31 | S8: 2031-32 | T8: 2032-33 | U8: 2033-34 | V8: 2034-35 | W8: 2035-36 | X8: 2036-37 | Y8: 2037-38 | Z8: 2038-39 | AA8: 2039-40 | AB8: 2040-41 | AC8: 2041-42 | AD8: 2042-43 | AE8: 2043-44 | AF8: 2044-45
B9: Return-to-aid | C9: =-'Model Summary'!F9*'Fee Revenue'!E20*2 -> 77.685702 | D9: =-'Model Summary'!I9*'Fee Revenue'!H20*2 -> 81.517037 | E9: =-'Model Summary'!L9*'Fee Revenue'!K20*2 -> 101.48118 | F9: =-'Model Summary'!O9*'Fee Revenue'!N20*2 -> 106.59458 | G9: =-'Model Summary'!R9*'Fee Revenue'!Q20*2 -> 111.70797 | H9: =-'Model Summary'!U9*'Fee Revenue'!T20*2 -> 116.18907 | I9: =-'Model Summary'!X9*'Fee Revenue'!W20*2 -> 121.30246 | J9: =-'Model Summary'!AA9*'Fee Revenue'!Z20*2 -> 127.04816 | K9: =-'Model Summary'!AD9*'Fee Revenue'!AC20*2 -> 132.79801 | L9: =-'Model Summary'!AG9*'Fee Revenue'!AF20*2 -> 138.57792 | M9: =-'Model Summary'!AJ9*'Fee Revenue'!AI20*2 -> 145.59653 | N9: =-'Model Summary'!AM9*'Fee Revenue'!AL20*2 -> 152.64522 | O9: =-'Model Summary'!AP9*'Fee Revenue'!AO20*2 -> 159.03151 | P9: =-'Model Summary'!AS9*'Fee Revenue'!AR20*2 -> 166.0802 | Q9: =-'Model Summary'!AV9*'Fee Revenue'!AU20*2 -> 173.76535 | R9: =-'Model Summary'!AY9*'Fee Revenue'!AX20*2 -> 181.4204 | S9: =-'Model Summary'!BB9*'Fee Revenue'!BA20*2 -> 189.74199 | T9: =-'Model Summary'!BE9*'Fee Revenue'!BD20*2 -> 198.69592 | U9: =-'Model Summary'!BH9*'Fee Revenue'!BG20*2 -> 208.32047 | V9: =-'Model Summary'!BK9*'Fee Revenue'!BJ20*2 -> 217.91084 | W9: =-'Model Summary'!BN9*'Fee Revenue'!BM20*2 -> 228.13764 | X9: =-'Model Summary'!BQ9*'Fee Revenue'!BP20*2 -> 239.66335 | Y9: =-'Model Summary'!BT9*'Fee Revenue'!BS20*2 -> 250.5567 | Z9: =-'Model Summary'!BW9*'Fee Revenue'!BV20*2 -> 262.71885 | AA9: =-'Model Summary'!BZ9*'Fee Revenue'!BY20*2 -> 275.51742 | AB9: =-'Model Summary'!CC9*'Fee Revenue'!CB20*2 -> 288.31599 | AC9: =-'Model Summary'!CF9*'Fee Revenue'!CE20*2 -> 301.78112 | AD9: =-'Model Summary'!CI9*'Fee Revenue'!CH20*2 -> 316.51506 | AE9: =-'Model Summary'!CL9*'Fee Revenue'!CK20*2 -> 331.25301 | AF9: =-'Model Summary'!CO9*'Fee Revenue'!CN20*2 -> 347.25577
B10: ISF Debt Service | C10: ='Model Summary'!F34*'Fee Revenue'!E20*2 -> 22.006891 | D10: ='Model Summary'!I34*'Fee Revenue'!H20*2 -> 16.259105 | E10: ='Model Summary'!L34*'Fee Revenue'!K20*2 -> 0 | F10: ='Model Summary'!O34*'Fee Revenue'!N20*2 -> 0 | G10: ='Model Summary'!R34*'Fee Revenue'!Q20*2 -> 0 | H10: ='Model Summary'!U34*'Fee Revenue'!T20*2 -> 0 | I10: ='Model Summary'!X34*'Fee Revenue'!W20*2 -> 0 | J10: ='Model Summary'!AA34*'Fee Revenue'!Z20*2 -> 0 | K10: ='Model Summary'!AD34*'Fee Revenue'!AC20*2 -> 0 | L10: ='Model Summary'!AG34*'Fee Revenue'!AF20*2 -> 0 | M10: ='Model Summary'!AJ34*'Fee Revenue'!AI20*2 -> 0 | N10: ='Model Summary'!AM34*'Fee Revenue'!AL20*2 -> 0 | O10: ='Model Summary'!AP34*'Fee Revenue'!AO20*2 -> 0 | P10: ='Model Summary'!AS34*'Fee Revenue'!AR20*2 -> 0 | Q10: ='Model Summary'!AV34*'Fee Revenue'!AU20*2 -> 0 | R10: ='Model Summary'!AY34*'Fee Revenue'!AX20*2 -> 0 | S10: ='Model Summary'!BB34*'Fee Revenue'!BA20*2 -> 0 | T10: ='Model Summary'!BE34*'Fee Revenue'!BD20*2 -> 0 | U10: ='Model Summary'!BH34*'Fee Revenue'!BG20*2 -> 0 | V10: ='Model Summary'!BK34*'Fee Revenue'!BJ20*2 -> 0 | W10: ='Model Summary'!BN34*'Fee Revenue'!BM20*2 -> 0 | X10: ='Model Summary'!BQ34*'Fee Revenue'!BP20*2 -> 0 | Y10: ='Model Summary'!BT34*'Fee Revenue'!BS20*2 -> 0 | Z10: ='Model Summary'!BW34*'Fee Revenue'!BV20*2 -> 0 | AA10: ='Model Summary'!BZ34*'Fee Revenue'!BY20*2 -> 0 | AB10: ='Model Summary'!CC34*'Fee Revenue'!CB20*2 -> 0 | AC10: ='Model Summary'!CF34*'Fee Revenue'!CE20*2 -> 0 | AD10: ='Model Summary'!CI34*'Fee Revenue'!CH20*2 -> 0 | AE10: ='Model Summary'!CL34*'Fee Revenue'!CK20*2 -> 0 | AF10: ='Model Summary'!CO34*'Fee Revenue'!CN20*2 -> 0
B11: RSF Existing Services | C11: ='Model Summary'!F32*'Fee Revenue'!E20*2 -> 116.03732 | D11: ='Model Summary'!I32*'Fee Revenue'!H20*2 -> 120.27752 | E11: ='Model Summary'!L32*'Fee Revenue'!K20*2 -> 123.46607 | F11: ='Model Summary'!O32*'Fee Revenue'!N20*2 -> 127.65527 | G11: ='Model Summary'!R32*'Fee Revenue'!Q20*2 -> 131.98873 | H11: ='Model Summary'!U32*'Fee Revenue'!T20*2 -> 136.48893 | I11: ='Model Summary'!X32*'Fee Revenue'!W20*2 -> 135.46184 | J11: ='Model Summary'!AA32*'Fee Revenue'!Z20*2 -> 140.43542 | K11: ='Model Summary'!AD32*'Fee Revenue'!AC20*2 -> 145.47231 | L11: ='Model Summary'!AG32*'Fee Revenue'!AF20*2 -> 150.71554 | M11: ='Model Summary'!AJ32*'Fee Revenue'!AI20*2 -> 156.14917 | N11: ='Model Summary'!AM32*'Fee Revenue'!AL20*2 -> 156.05297 | O11: ='Model Summary'!AP32*'Fee Revenue'!AO20*2 -> 161.79259 | P11: ='Model Summary'!AS32*'Fee Revenue'!AR20*2 -> 167.82863 | Q11: ='Model Summary'!AV32*'Fee Revenue'!AU20*2 -> 174.041 | R11: ='Model Summary'!AY32*'Fee Revenue'!AX20*2 -> 180.43388 | S11: ='Model Summary'!BB32*'Fee Revenue'!BA20*2 -> 187.04775 | T11: ='Model Summary'!BE32*'Fee Revenue'!BD20*2 -> 193.95211 | U11: ='Model Summary'!BH32*'Fee Revenue'!BG20*2 -> 200.99971 | V11: ='Model Summary'!BK32*'Fee Revenue'!BJ20*2 -> 208.34902 | W11: ='Model Summary'!BN32*'Fee Revenue'!BM20*2 -> 215.91996 | X11: ='Model Summary'!BQ32*'Fee Revenue'!BP20*2 -> 223.8122 | Y11: ='Model Summary'!BT32*'Fee Revenue'!BS20*2 -> 231.90556 | Z11: ='Model Summary'!BW32*'Fee Revenue'!BV20*2 -> 240.30813 | AA11: ='Model Summary'!BZ32*'Fee Revenue'!BY20*2 -> 248.96719 | AB11: ='Model Summary'!CC32*'Fee Revenue'!CB20*2 -> 257.91739 | AC11: ='Model Summary'!CF32*'Fee Revenue'!CE20*2 -> 267.17064 | AD11: ='Model Summary'!CI32*'Fee Revenue'!CH20*2 -> 276.76867 | AE11: ='Model Summary'!CL32*'Fee Revenue'!CK20*2 -> 286.60518 | AF11: ='Model Summary'!CO32*'Fee Revenue'!CN20*2 -> 296.88797
B12: RSF equip/maint reserves | C12: ='Model Summary'!F36*'Fee Revenue'!E20*2 -> 2.3488507 | D12: ='Model Summary'!I36*'Fee Revenue'!H20*2 -> 8.5221373 | E12: ='Model Summary'!L36*'Fee Revenue'!K20*2 -> 12.208283 | F12: ='Model Summary'!O36*'Fee Revenue'!N20*2 -> 13.511052 | G12: ='Model Summary'!R36*'Fee Revenue'!Q20*2 -> 14.669416 | H12: ='Model Summary'!U36*'Fee Revenue'!T20*2 -> 14.349438 | I12: ='Model Summary'!X36*'Fee Revenue'!W20*2 -> 20.868736 | J12: ='Model Summary'!AA36*'Fee Revenue'!Z20*2 -> 21.277218 | K12: ='Model Summary'!AD36*'Fee Revenue'!AC20*2 -> 21.698148 | L12: ='Model Summary'!AG36*'Fee Revenue'!AF20*2 -> 22.146903 | M12: ='Model Summary'!AJ36*'Fee Revenue'!AI20*2 -> 23.446178 | N12: ='Model Summary'!AM36*'Fee Revenue'!AL20*2 -> 30.507739 | O12: ='Model Summary'!AP36*'Fee Revenue'!AO20*2 -> 30.194077 | P12: ='Model Summary'!AS36*'Fee Revenue'!AR20*2 -> 29.701428 | Q12: ='Model Summary'!AV36*'Fee Revenue'!AU20*2 -> 30.420225 | R12: ='Model Summary'!AY36*'Fee Revenue'!AX20*2 -> 30.726739 | S12: ='Model Summary'!BB36*'Fee Revenue'!BA20*2 -> 31.012475 | T12: ='Model Summary'!BE36*'Fee Revenue'!BD20*2 -> 32.308948 | U12: ='Model Summary'!BH36*'Fee Revenue'!BG20*2 -> 33.750907 | V12: ='Model Summary'!BK36*'Fee Revenue'!BJ20*2 -> 34.570685 | W12: ='Model Summary'!BN36*'Fee Revenue'!BM20*2 -> 35.138238 | X12: ='Model Summary'!BQ36*'Fee Revenue'!BP20*2 -> 36.881835 | Y12: ='Model Summary'!BT36*'Fee Revenue'!BS20*2 -> 37.125373 | Z12: ='Model Summary'!BW36*'Fee Revenue'!BV20*2 -> 38.326879 | AA12: ='Model Summary'!BZ36*'Fee Revenue'!BY20*2 -> 39.24212 | AB12: ='Model Summary'!CC36*'Fee Revenue'!CB20*2 -> 39.865883 | AC12: ='Model Summary'!CF36*'Fee Revenue'!CE20*2 -> 40.385399 | AD12: ='Model Summary'!CI36*'Fee Revenue'!CH20*2 -> 41.824921 | AE12: ='Model Summary'!CL36*'Fee Revenue'!CK20*2 -> 41.705255 | AF12: ='Model Summary'!CO36*'Fee Revenue'!CN20*2 -> 42.300128
B13: New Services | C13: ='Model Summary'!F60*'Fee Revenue'!E20*2 -> 73.921231 | D13: ='Model Summary'!I60*'Fee Revenue'!H20*2 -> 77.586989 | E13: ='Model Summary'!L60*'Fee Revenue'!K20*2 -> 81.427767 | F13: ='Model Summary'!O60*'Fee Revenue'!N20*2 -> 86.101442 | G13: ='Model Summary'!R60*'Fee Revenue'!Q20*2 -> 91.07108 | H13: ='Model Summary'!U60*'Fee Revenue'!T20*2 -> 96.300674 | I13: ='Model Summary'!X60*'Fee Revenue'!W20*2 -> 101.9223 | J13: ='Model Summary'!AA60*'Fee Revenue'!Z20*2 -> 107.96085 | K13: ='Model Summary'!AD60*'Fee Revenue'!AC20*2 -> 114.30363 | L13: ='Model Summary'!AG60*'Fee Revenue'!AF20*2 -> 121.08155 | M13: ='Model Summary'!AJ60*'Fee Revenue'!AI20*2 -> 128.30609 | N13: ='Model Summary'!AM60*'Fee Revenue'!AL20*2 -> 136.02427 | O13: ='Model Summary'!AP60*'Fee Revenue'!AO20*2 -> 144.1537 | P13: ='Model Summary'!AS60*'Fee Revenue'!AR20*2 -> 152.90306 | Q13: ='Model Summary'!AV60*'Fee Revenue'!AU20*2 -> 162.19651 | R13: ='Model Summary'!AY60*'Fee Revenue'!AX20*2 -> 172.06842 | S13: ='Model Summary'!BB60*'Fee Revenue'!BA20*2 -> 182.59067 | T13: ='Model Summary'!BE60*'Fee Revenue'!BD20*2 -> 193.86983 | U13: ='Model Summary'!BH60*'Fee Revenue'!BG20*2 -> 205.79936 | V13: ='Model Summary'!BK60*'Fee Revenue'!BJ20*2 -> 218.58118 | W13: ='Model Summary'!BN60*'Fee Revenue'!BM20*2 -> 232.17929 | X13: ='Model Summary'!BQ60*'Fee Revenue'!BP20*2 -> 246.75006 | Y13: ='Model Summary'!BT60*'Fee Revenue'!BS20*2 -> 262.21514 | Z13: ='Model Summary'!BW60*'Fee Revenue'!BV20*2 -> 278.75031 | AA13: ='Model Summary'!BZ60*'Fee Revenue'!BY20*2 -> 296.35572 | AB13: ='Model Summary'!CC60*'Fee Revenue'!CB20*2 -> 315.13535 | AC13: ='Model Summary'!CF60*'Fee Revenue'!CE20*2 -> 335.17267 | AD13: ='Model Summary'!CI60*'Fee Revenue'!CH20*2 -> 356.595 | AE13: ='Model Summary'!CL60*'Fee Revenue'!CK20*2 -> 379.34382 | AF13: ='Model Summary'!CO60*'Fee Revenue'!CN20*2 -> 403.77702
B14: TOTAL | C14: =SUM(C9:C13) -> 292 | D14: =SUM(D9:D13) -> 304.16279 | E14: =SUM(E9:E13) -> 318.5833 | F14: =SUM(F9:F13) -> 333.86234 | G14: =SUM(G9:G13) -> 349.4372 | H14: =SUM(H9:H13) -> 363.32811 | I14: =SUM(I9:I13) -> 379.55534 | J14: =SUM(J9:J13) -> 396.72164 | ... AF14: =SUM(AF9:AF13) -> 1090.2209

Sheet Model Summary
B2: Wellness Referendum Model
B3: Model Summary – 30 years
B4: prepared by Hugh G. Graham, Campus Budget Office | D4: 2015-16 | G4: 2016-17 | J4: 2017-18 | M4: 2018-19 | P4: 2019-20 | S4: 2020-21 | V4: 2021-22 | Y4: 2022-23 | AB4: 2023-24 | AE4: 2024-25 | AH4: 2025-26 | AK4: 2026-27 | AN4: 2027-28 | AQ4: 2028-29 | AT4: 2029-30 | AW4: 2030-31 | AZ4: 2031-32 | BC4: 2032-33 | BF4: 2033-34 | BI4: 2034-35 | BL4: 2035-36 | BO4: 2036-37 | BR4: 2037-38 | BU4: 2038-39 | BX4: 2039-40 | CA4: 2040-41 | CD4: 2041-42 | CG4: 2042-43 | CJ4: 2043-44 | CM4: 2044-45
B5: REVISED DRAFT 2/26/15 | D5: $ | E5: % growth | F5: % of gross fee | G5: $ | H5: % growth | I5: % of gross fee | J5: $ | K5: % growth | L5: % of gross fee | M5: $ | N5: % growth | O5: % of gross fee | P5: $ | Q5: % growth | R5: % of gross fee | S5: $ | T5: % growth | U5: % of gross fee | V5: $ | W5: % growth | X5: % of gross fee | Y5: $ | Z5: % growth | AA5: % of gross fee | AB5: $ | AC5: % growth | AD5: % of gross fee | AE5: $ | AF5: % growth | AG5: % of gross fee | AH5: $ | AI5: % growth | AJ5: % of gross fee | AK5: $ | AL5: % growth | AM5: % of gross fee | AN5: $ | AO5: % growth | AP5: % of gross fee | AQ5: $ | AR5: % growth | AS5: % of gross fee | AT5: $ | AU5: % growth | AV5: % of gross fee | AW5: $ | AX5: % growth | AY5: % of gross fee | AZ5: $ | BA5: % growth | BB5: % of gross fee | BC5: $ | BD5: % growth | BE5: % of gross fee | BF5: $ | BG5: % growth | BH5: % of gross fee | BI5: $ | BJ5: % growth | BK5: % of gross fee | BL5: $ | BM5: % growth | BN5: % of gross fee | BO5: $ | BP5: % growth | BQ5: % of gross fee | BR5: $ | BS5: % growth | BT5: % of gross fee | BU5: $ | BV5: % growth | BW5: % of gross fee | BX5: $ | BY5: % growth | BZ5: % of gross fee | CA5: $ | CB5: % growth | CC5: % of gross fee | CD5: $ | CE5: % growth | CF5: % of gross fee | CG5: $ | CH5: % growth | CI5: % of gross fee | CJ5: $ | CK5: % growth | CL5: % of gross fee | CM5: $ | CN5: % growth | CO5: % of gross fee
B6: REVENUE / INFLOWS
B7: 1 | C7: Net Fee Revenue - TOTAL
B8: a. | C8: Gross Fee Revenue | D8: ='Fee Revenue'!E70+'Fee Revenue'!E72+'Fee Revenue'!E74 -> 12236250 | E8: n/a | F8: =D8/D8 -> 1 | G8: ='Fee Revenue'!H70+'Fee Revenue'!H72+'Fee Revenue'!H74 -> 12825000 | H8: =(G8-D8)/D8 -> 0.048115231 | I8: =G8/G8 -> 1 | J8: ='Fee Revenue'!K70+'Fee Revenue'!K72+'Fee Revenue'!K74 -> 13511500 | K8: =(J8-G8)/G8 -> 0.053528265 | L8: =J8/J8 -> 1 | M8: ='Fee Revenue'!N70+'Fee Revenue'!N72+'Fee Revenue'!N74 -> 14190500 | N8: =(M8-J8)/J8 -> 0.050253488 | O8: =M8/M8 -> 1 | P8: ='Fee Revenue'!Q70+'Fee Revenue'!Q72+'Fee Revenue'!Q74 -> 14869500 | Q8: =(P8-M8)/M8 -> 0.047848913 | R8: =P8/P8 -> 1 | S8: ='Fee Revenue'!T70+'Fee Revenue'!T72+'Fee Revenue'!T74 -> 15472500 | T8: =(S8-P8)/P8 -> 0.040552809 | U8: =S8/S8 -> 1 | V8: ='Fee Revenue'!W70+'Fee Revenue'!W72+'Fee Revenue'!W74 -> 16151500 | W8: =(V8-S8)/S8 -> 0.043884311 | X8: =V8/V8 -> 1 | Y8: ='Fee Revenue'!Z70+'Fee Revenue'!Z72+'Fee Revenue'!Z74 -> 16906500 | Z8: =(Y8-V8)/V8 -> 0.046744884 | AA8: =Y8/Y8 -> 1 | AB8: ='Fee Revenue'!AC70+'Fee Revenue'!AC72+'Fee Revenue'!AC74 -> 17674000 | AC8: =(AB8-Y8)/Y8 -> 0.045396741 | AD8: =AB8/AB8 -> 1 | AE8: ='Fee Revenue'!AF70+'Fee Revenue'!AF72+'Fee Revenue'!AF74 -> 18437500 | AF8: =(AE8-AB8)/AB8 -> 0.043199049 | AG8: =AE8/AE8 -> 1 | AH8: ='Fee Revenue'!AI70+'Fee Revenue'!AI72+'Fee Revenue'!AI74 -> 19369500 | AI8: =(AH8-AE8)/AE8 -> 0.050549153 | AJ8: =AH8/AH8 -> 1 | AK8: ='Fee Revenue'!AL70+'Fee Revenue'!AL72+'Fee Revenue'!AL74 -> 20297500 | AL8: =(AK8-AH8)/AH8 -> 0.047910375 | AM8: =AK8/AK8 -> 1 | AN8: ='Fee Revenue'!AO70+'Fee Revenue'!AO72+'Fee Revenue'!AO74 -> 21153500 | AO8: =(AN8-AK8)/AK8 -> 0.042172681 | AP8: =AN8/AN8 -> 1 | AQ8: ='Fee Revenue'!AR70+'Fee Revenue'!AR72+'Fee Revenue'!AR74 -> 22081500 | AR8: =(AQ8-AN8)/AN8 -> 0.043869809 | AS8: =AQ8/AQ8 -> 1 | AT8: ='Fee Revenue'!AU70+'Fee Revenue'!AU72+'Fee Revenue'!AU74 -> 23098000 | AU8: =(AT8-AQ8)/AQ8 -> 0.04603401 | AV8: =AT8/AT8 -> 1 | AW8: ='Fee Revenue'!AX70+'Fee Revenue'!AX72+'Fee Revenue'!AX74 -> 24118500 | AX8: =(AW8-AT8)/AT8 -> 0.044181314 | AY8: =AW8/AW8 -> 1 | AZ8: ='Fee Revenue'!BA70+'Fee Revenue'!BA72+'Fee Revenue'!BA74 -> 25223500 | BA8: =(AZ8-AW8)/AW8 -> 0.045815453 | BB8: =AZ8/AZ8 -> 1 | BC8: ='Fee Revenue'!BD70+'Fee Revenue'!BD72+'Fee Revenue'!BD74 -> 26404500 | BD8: =(BC8-AZ8)/AZ8 -> 0.046821417 | BE8: =BC8/BC8 -> 1 | BF8: ='Fee Revenue'!BG70+'Fee Revenue'!BG72+'Fee Revenue'!BG74 -> 27682500 | BG8: =(BF8-BC8)/BC8 -> 0.048400841 | BH8: =BF8/BF8 -> 1 | BI8: ='Fee Revenue'!BJ70+'Fee Revenue'!BJ72+'Fee Revenue'!BJ74 -> 28952000 | BJ8: =(BI8-BF8)/BF8 -> 0.045859297 | BK8: =BI8/BI8 -> 1 | BL8: ='Fee Revenue'!BM70+'Fee Revenue'!BM72+'Fee Revenue'!BM74 -> 30310000 | BM8: =(BL8-BI8)/BI8 -> 0.046905222 | BN8: =BL8/BL8 -> 1 | BO8: ='Fee Revenue'!BP70+'Fee Revenue'!BP72+'Fee Revenue'!BP74 -> 31828500 | BP8: =(BO8-BL8)/BL8 -> 0.050098977 | BQ8: =BO8/BO8 -> 1 | BR8: ='Fee Revenue'!BS70+'Fee Revenue'!BS72+'Fee Revenue'!BS74 -> 33271000 | BS8: =(BR8-BO8)/BO8 -> 0.045321017 | BT8: =BR8/BR8 -> 1 | BU8: ='Fee Revenue'!BV70+'Fee Revenue'!BV72+'Fee Revenue'!BV74 -> 34878000 | BV8: =(BU8-BR8)/BR8 -> 0.048300322 | BW8: =BU8/BU8 -> 1 | BX8: ='Fee Revenue'!BY70+'Fee Revenue'!BY72+'Fee Revenue'!BY74 -> 36573500 | BY8: =(BX8-BU8)/BU8 -> 0.048612306 | BZ8: =BX8/BX8 -> 1 | CA8: ='Fee Revenue'!CB70+'Fee Revenue'!CB72+'Fee Revenue'!CB74 -> 38269000 | CB8: =(CA8-BX8)/BX8 -> 0.046358702 | CC8: =CA8/CA8 -> 1 | CD8: ='Fee Revenue'!CE70+'Fee Revenue'!CE72+'Fee Revenue'!CE74 -> 40049000 | CE8: =(CD8-CA8)/CA8 -> 0.046512843 | CF8: =CD8/CD8 -> 1 | CG8: ='Fee Revenue'!CH70+'Fee Revenue'!CH72+'Fee Revenue'!CH74 -> 41993500 | CH8: =(CG8-CD8)/CD8 -> 0.048553023 | CI8: =CG8/CG8 -> 1 | CJ8: ='Fee Revenue'!CK70+'Fee Revenue'!CK72+'Fee Revenue'!CK74 -> 43950500 | CK8: =(CJ8-CG8)/CG8 -> 0.04660245 | CL8: =CJ8/CJ8 -> 1 | CM8: ='Fee Revenue'!CN70+'Fee Revenue'!CN72+'Fee Revenue'!CN74 -> 46059500 | CN8: =(CM8-CJ8)/CJ8 -> 0.047985802 | CO8: =CM8/CM8 -> 1
B9: b. | C9: Less: Return-to-Aid (UC students only) | D9: ='Fee Revenue'!E71+'Fee Revenue'!E73 -> -3255416.7 | E9: n/a | F9: =D9/D8 -> -0.26604692 | G9: ='Fee Revenue'!H71+'Fee Revenue'!H73 -> -3439000 | H9: =(G9-D9)/D9 -> 0.056393191 | I9: =G9/G8 -> -0.26814815 | J9: ='Fee Revenue'!K71+'Fee Revenue'!K73 -> -4311833.3 | K9: =(J9-G9)/G9 -> 0.2538044 | L9: =J9/J8 -> -0.31912322 | M9: ='Fee Revenue'!N71+'Fee Revenue'!N73 -> -4528833.3 | N9: =(M9-J9)/J9 -> 0.050326621 | O9: =M9/M8 -> -0.31914544 | P9: ='Fee Revenue'!Q71+'Fee Revenue'!Q73 -> -4745833.3 | Q9: =(P9-M9)/M9 -> 0.04791521 | R9: =P9/P8 -> -0.31916563 | S9: ='Fee Revenue'!T71+'Fee Revenue'!T73 -> -4938833.3 | T9: =(S9-P9)/P9 -> 0.040667252 | U9: =S9/S8 -> -0.31920073 | V9: ='Fee Revenue'!W71+'Fee Revenue'!W73 -> -5155833.3 | W9: =(V9-S9)/S9 -> 0.043937502 | X9: =V9/V8 -> -0.319217 | Y9: ='Fee Revenue'!Z71+'Fee Revenue'!Z73 -> -5396833.3 | Z9: =(Y9-V9)/V9 -> 0.046743171 | AA9: =Y9/Y8 -> -0.31921647 | AB9: ='Fee Revenue'!AC71+'Fee Revenue'!AC73 -> -5642000 | AC9: =(AB9-Y9)/Y9 -> 0.045427874 | AD9: =AB9/AB8 -> -0.31922598 | AE9: ='Fee Revenue'!AF71+'Fee Revenue'!AF73 -> -5887166.7 | AF9: =(AE9-AB9)/AB9 -> 0.043453858 | AG9: =AE9/AE8 -> -0.31930395 | AH9: ='Fee Revenue'!AI71+'Fee Revenue'!AI73 -> -6184500 | AI9: =(AH9-AE9)/AE9 -> 0.050505336 | AJ9: =AH9/AH8 -> -0.31929064 | AK9: ='Fee Revenue'!AL71+'Fee Revenue'!AL73 -> -6481833.3 | AL9: =(AK9-AH9)/AH9 -> 0.048077182 | AM9: =AK9/AK8 -> -0.31934146 | AN9: ='Fee Revenue'!AO71+'Fee Revenue'!AO73 -> -6755166.7 | AO9: =(AN9-AK9)/AK9 -> 0.042169139 | AP9: =AN9/AN8 -> -0.31934038 | AQ9: ='Fee Revenue'!AR71+'Fee Revenue'!AR73 -> -7052500 | AR9: =(AQ9-AN9)/AN9 -> 0.044015692 | AS9: =AQ9/AQ8 -> -0.31938501 | AT9: ='Fee Revenue'!AU71+'Fee Revenue'!AU73 -> -7378000 | AU9: =(AT9-AQ9)/AQ9 -> 0.046153846 | AV9: =AT9/AT8 -> -0.31942159 | AW9: ='Fee Revenue'!AX71+'Fee Revenue'!AX73 -> -7703500 | AX9: =(AW9-AT9)/AT9 -> 0.044117647 | AY9: =AW9/AW8 -> -0.31940212 | AZ9: ='Fee Revenue'!BA71+'Fee Revenue'!BA73 -> -8057166.7 | BA9: =(AZ9-AW9)/AW9 -> 0.045909868 | BB9: =AZ9/AZ8 -> -0.31943095 | BC9: ='Fee Revenue'!BD71+'Fee Revenue'!BD73 -> -8434833.3 | BD9: =(BC9-AZ9)/AZ9 -> 0.046873384 | BE9: =BC9/BC8 -> -0.31944681 | BF9: ='Fee Revenue'!BG71+'Fee Revenue'!BG73 -> -8844833.3 | BG9: =(BF9-BC9)/BC9 -> 0.048607955 | BH9: =BF9/BF8 -> -0.31950992 | BI9: ='Fee Revenue'!BJ71+'Fee Revenue'!BJ73 -> -9250666.7 | BJ9: =(BI9-BF9)/BF9 -> 0.045883661 | BK9: =BI9/BI8 -> -0.31951736 | BL9: ='Fee Revenue'!BM71+'Fee Revenue'!BM73 -> -9684666.7 | BM9: =(BL9-BI9)/BI9 -> 0.046915538 | BN9: =BL9/BL8 -> -0.31952051 | BO9: ='Fee Revenue'!BP71+'Fee Revenue'!BP73 -> -10170833 | BP9: =(BO9-BL9)/BL9 -> 0.050199628 | BQ9: =BO9/BO8 -> -0.31955114 | BR9: ='Fee Revenue'!BS71+'Fee Revenue'!BS73 -> -10633000 | BS9: =(BR9-BO9)/BO9 -> 0.045440393 | BT9: =BR9/BR8 -> -0.31958763 | BU9: ='Fee Revenue'!BV71+'Fee Revenue'!BV73 -> -11147333 | BV9: =(BU9-BR9)/BR9 -> 0.048371422 | BW9: =BU9/BU8 -> -0.3196093 | BX9: ='Fee Revenue'!BY71+'Fee Revenue'!BY73 -> -11689833 | BY9: =(BX9-BU9)/BU9 -> 0.048666348 | BZ9: =BX9/BX8 -> -0.31962578 | CA9: ='Fee Revenue'!CB71+'Fee Revenue'!CB73 -> -12232333 | CB9: =(CA9-BX9)/BX9 -> 0.046407847 | CC9: =CA9/CA8 -> -0.31964079 | CD9: ='Fee Revenue'!CE71+'Fee Revenue'!CE73 -> -12803000 | CE9: =(CD9-CA9)/CA9 -> 0.046652315 | CF9: =CD9/CD8 -> -0.31968339 | CG9: ='Fee Revenue'!CH71+'Fee Revenue'!CH73 -> -13425833 | CH9: =(CG9-CD9)/CD9 -> 0.048647452 | CI9: =CG9/CG8 -> -0.31971218 | CJ9: ='Fee Revenue'!CK71+'Fee Revenue'!CK73 -> -14052833 | CK9: =(CJ9-CG9)/CG9 -> 0.046701012 | CL9: =CJ9/CJ8 -> -0.31974229 | CM9: ='Fee Revenue'!CN71+'Fee Revenue'!CN73 -> -14727833 | CN9: =(CM9-CJ9)/CJ9 -> 0.048033018 | CO9: =CM9/CM8 -> -0.31975669
B10: c. | C10: TOTAL NET FEE REVENUE (= line 3) | D10: ='Fee Revenue'!E75 -> 8980833.3 | E10: n/a | F10: =D10/D8 -> 0.73395308 | G10: ='Fee Revenue'!H75 -> 9386000 | H10: =(G10-D10)/D10 -> 0.045114596 | I10: =G10/G8 -> 0.73185185 | J10: ='Fee Revenue'!K75 -> 9199666.7 | K10: =(J10-G10)/G10 -> -0.019852262 | L10: =J10/J8 -> 0.68087678 | M10: ='Fee Revenue'!N75 -> 9661666.7 | N10: =(M10-J10)/J10 -> 0.050219211 | O10: =M10/M8 -> 0.68085456 | P10: ='Fee Revenue'!Q75 -> 10123667 | Q10: =(P10-M10)/M10 -> 0.047817837 | R10: =P10/P8 -> 0.68083437 | S10: ='Fee Revenue'!T75 -> 10533667 | T10: =(S10-P10)/P10 -> 0.04049916 | U10: =S10/S8 -> 0.68079927 | V10: ='Fee Revenue'!W75 -> 10995667 | W10: =(V10-S10)/S10 -> 0.043859372 | X10: =V10/V8 -> 0.680783 | Y10: ='Fee Revenue'!Z75 -> 11509667 | Z10: =(Y10-V10)/V10 -> 0.046745688 | AA10: =Y10/Y8 -> 0.68078353 | AB10: ='Fee Revenue'!AC75 -> 12032000 | AC10: =(AB10-Y10)/Y10 -> 0.045382143 | AD10: =AB10/AB8 -> 0.68077402 | AE10: ='Fee Revenue'!AF75 -> 12550333 | AF10: =(AE10-AB10)/AB10 -> 0.043079566 | AG10: =AE10/AE8 -> 0.68069605 | AH10: ='Fee Revenue'!AI75 -> 13185000 | AI10: =(AH10-AE10)/AE10 -> 0.050569706 | AJ10: =AH10/AH8 -> 0.68070936 | AK10: ='Fee Revenue'!AL75 -> 13815667 | AL10: =(AK10-AH10)/AH10 -> 0.047832132 | AM10: =AK10/AK8 -> 0.68065854 | AN10: ='Fee Revenue'!AO75 -> 14398333 | AO10: =(AN10-AK10)/AK10 -> 0.042174343 | AP10: =AN10/AN8 -> 0.68065962 | AQ10: ='Fee Revenue'!AR75 -> 15029000 | AR10: =(AQ10-AN10)/AN10 -> 0.043801366 | AS10: =AQ10/AQ8 -> 0.68061499 | AT10: ='Fee Revenue'!AU75 -> 15720000 | AU10: =(AT10-AQ10)/AQ10 -> 0.045977776 | AV10: =AT10/AT8 -> 0.68057841 | AW10: ='Fee Revenue'!AX75 -> 16415000 | AX10: =(AW10-AT10)/AT10 -> 0.044211196 | AY10: =AW10/AW8 -> 0.68059788 | AZ10: ='Fee Revenue'!BA75 -> 17166333 | BA10: =(AZ10-AW10)/AW10 -> 0.045771144 | BB10: =AZ10/AZ8 -> 0.68056905 | BC10: ='Fee Revenue'!BD75 -> 17969667 | BD10: =(BC10-AZ10)/AZ10 -> 0.046797025 | BE10: =BC10/BC8 -> 0.68055319 | BF10: ='Fee Revenue'!BG75 -> 18837667 | BG10: =(BF10-BC10)/BC10 -> 0.048303623 | BH10: =BF10/BF8 -> 0.68049008 | BI10: ='Fee Revenue'!BJ75 -> 19701333 | BJ10: =(BI10-BF10)/BF10 -> 0.045847858 | BK10: =BI10/BI8 -> 0.68048264 | BL10: ='Fee Revenue'!BM75 -> 20625333 | BM10: =(BL10-BI10)/BI10 -> 0.046900379 | BN10: =BL10/BL8 -> 0.68047949 | BO10: ='Fee Revenue'!BP75 -> 21657667 | BP10: =(BO10-BL10)/BL10 -> 0.050051716 | BQ10: =BO10/BO8 -> 0.68044886 | BR10: ='Fee Revenue'!BS75 -> 22638000 | BS10: =(BR10-BO10)/BO10 -> 0.045264956 | BT10: =BR10/BR8 -> 0.68041237 | BU10: ='Fee Revenue'!BV75 -> 23730667 | BV10: =(BU10-BR10)/BR10 -> 0.048266926 | BW10: =BU10/BU8 -> 0.6803907 | BX10: ='Fee Revenue'!BY75 -> 24883667 | BY10: =(BX10-BU10)/BU10 -> 0.04858692 | BZ10: =BX10/BX8 -> 0.68037422 | CA10: ='Fee Revenue'!CB75 -> 26036667 | CB10: =(CA10-BX10)/BX10 -> 0.046335615 | CC10: =CA10/CA8 -> 0.68035921 | CD10: ='Fee Revenue'!CE75 -> 27246000 | CE10: =(CD10-CA10)/CA10 -> 0.046447318 | CF10: =CD10/CD8 -> 0.68031661 | CG10: ='Fee Revenue'!CH75 -> 28567667 | CH10: =(CG10-CD10)/CD10 -> 0.04850865 | CI10: =CG10/CG8 -> 0.68028782 | CJ10: ='Fee Revenue'!CK75 -> 29897667 | CK10: =(CJ10-CG10)/CG10 -> 0.04655613 | CL10: =CJ10/CJ8 -> 0.68025771 | CM10: ='Fee Revenue'!CN75 -> 31331667 | CN10: =(CM10-CJ10)/CJ10 -> 0.047963609 | CO10: =CM10/CM8 -> 0.68024331
B12: 2 | C12: Net Fee Revenue - BREAKDOWN
B13: a. | C13: RSF Base Fee Revenue | D13: ='Fee Revenue'!E51 -> 5370333.3 | E13: n/a | F13: =D13/D$8 -> 0.43888719 | G13: ='Fee Revenue'!H51 -> 5591750 | I13: =G13/G$8 -> 0.4360039 | J13: ='Fee Revenue'!K51 -> 5221666.7 | L13: =J13/J$8 -> 0.38646092 | M13: ='Fee Revenue'!N51 -> 5439583.3 | O13: =M13/M$8 -> 0.3833257 | P13: ='Fee Revenue'!Q51 -> 5657500 | R13: =P13/P$8 -> 0.38047682 | S13: ='Fee Revenue'!T51 -> 5823416.7 | U13: =S13/S$8 -> 0.37637206 | V13: ='Fee Revenue'!W51 -> 6041333.3 | X13: =V13/V$8 -> 0.37404163 | Y13: ='Fee Revenue'!Z51 -> 6250916.7 | AA13: =Y13/Y$8 -> 0.36973452 | AB13: ='Fee Revenue'!AC51 -> 6468833.3 | AD13: =AB13/AB$8 -> 0.36600845 | AE13: ='Fee Revenue'!AF51 -> 6695083.3 | AG13: =AE13/AE$8 -> 0.36312316 | AH13: ='Fee Revenue'!AI51 -> 6965000 | AJ13: =AH13/AH$8 -> 0.35958595 | AK13: ='Fee Revenue'!AL51 -> 7243250 | AM13: =AK13/AK$8 -> 0.35685429 | AN13: ='Fee Revenue'!AO51 -> 7461166.7 | AP13: =AN13/AN$8 -> 0.35271547 | AQ13: ='Fee Revenue'!AR51 -> 7679083.3 | AS13: =AQ13/AQ$8 -> 0.34776095 | AT13: ='Fee Revenue'!AU51 -> 7957333.3 | AV13: =AT13/AT$8 -> 0.34450313 | AW13: ='Fee Revenue'!AX51 -> 8227250 | AY13: =AW13/AW$8 -> 0.34111781 | AZ13: ='Fee Revenue'!BA51 -> 8505500 | BB13: =AZ13/AZ$8 -> 0.33720538 | BC13: ='Fee Revenue'!BD51 -> 8820666.7 | BE13: =BC13/BC$8 -> 0.33405922 | BF13: ='Fee Revenue'!BG51 -> 9152500 | BH13: =BF13/BF$8 -> 0.33062404 | BI13: ='Fee Revenue'!BJ51 -> 9467666.7 | BK13: =BI13/BI$8 -> 0.32701253 | BL13: ='Fee Revenue'!BM51 -> 9782833.3 | BN13: =BL13/BL$8 -> 0.32275927 | BO13: ='Fee Revenue'!BP51 -> 10158333 | BQ13: =BO13/BO$8 -> 0.31915841 | BR13: ='Fee Revenue'!BS51 -> 10481833 | BT13: =BR13/BR$8 -> 0.31504413 | BU13: ='Fee Revenue'!BV51 -> 10857333 | BW13: =BU13/BU$8 -> 0.31129461 | BX13: ='Fee Revenue'!BY51 -> 11232833 | BZ13: =BX13/BX$8 -> 0.30713039 | CA13: ='Fee Revenue'!CB51 -> 11608333 | CC13: =CA13/CA$8 -> 0.30333516 | CD13: ='Fee Revenue'!CE51 -> 11992167 | CF13: =CD13/CD$8 -> 0.29943736 | CG13: ='Fee Revenue'!CH51 -> 12428000 | CI13: =CG13/CG$8 -> 0.29595056 | CJ13: ='Fee Revenue'!CK51 -> 12811833 | CL13: =CJ13/CJ$8 -> 0.29150597 | CM13: ='Fee Revenue'!CN51 -> 13239333 | CO13: =CM13/CM$8 -> 0.2874398
B14: b. | C14: RSF Membership Fee Buy-Out Revenue | D14: ='Fee Revenue'!E59 -> 512833.33 | E14: n/a | F14: =D14/D$8 -> 0.041910989 | G14: ='Fee Revenue'!H59 -> 527916.67 | I14: =G14/G$8 -> 0.041163093 | J14: ='Fee Revenue'!K59 -> 543000 | L14: =J14/J$8 -> 0.040187988 | M14: ='Fee Revenue'!N59 -> 558083.33 | O14: =M14/M$8 -> 0.039327954 | P14: ='Fee Revenue'!Q59 -> 573166.67 | R14: =P14/P$8 -> 0.038546465 | S14: ='Fee Revenue'!T59 -> 588250 | U14: =S14/S$8 -> 0.038019066 | V14: ='Fee Revenue'!W59 -> 603333.33 | X14: =V14/V$8 -> 0.037354632 | Y14: ='Fee Revenue'!Z59 -> 618416.67 | AA14: =Y14/Y$8 -> 0.036578633 | AB14: ='Fee Revenue'!AC59 -> 633500 | AD14: =AB14/AB$8 -> 0.035843612 | AE14: ='Fee Revenue'!AF59 -> 648583.33 | AG14: =AE14/AE$8 -> 0.035177401 | AH14: ='Fee Revenue'!AI59 -> 663666.67 | AJ14: =AH14/AH$8 -> 0.03426349 | AK14: ='Fee Revenue'!AL59 -> 678750 | AM14: =AK14/AK$8 -> 0.033440079 | AN14: ='Fee Revenue'!AO59 -> 693833.33 | AP14: =AN14/AN$8 -> 0.032799931 | AQ14: ='Fee Revenue'!AR59 -> 708916.67 | AS14: =AQ14/AQ$8 -> 0.032104552 | AT14: ='Fee Revenue'!AU59 -> 724000 | AV14: =AT14/AT$8 -> 0.031344705 | AW14: ='Fee Revenue'!AX59 -> 739083.33 | AY14: =AW14/AW$8 -> 0.030643835 | AZ14: ='Fee Revenue'!BA59 -> 754166.67 | BB14: =AZ14/AZ$8 -> 0.029899366 | BC14: ='Fee Revenue'!BD59 -> 784333.33 | BE14: =BC14/BC$8 -> 0.029704533 | BF14: ='Fee Revenue'!BG59 -> 814500 | BH14: =BF14/BF$8 -> 0.029422921 | BI14: ='Fee Revenue'!BJ59 -> 844666.67 | BK14: =BI14/BI$8 -> 0.029174726 | BL14: ='Fee Revenue'!BM59 -> 874833.33 | BN14: =BL14/BL$8 -> 0.028862862 | BO14: ='Fee Revenue'!BP59 -> 905000 | BQ14: =BO14/BO$8 -> 0.028433637 | BR14: ='Fee Revenue'!BS59 -> 935166.67 | BT14: =BR14/BR$8 -> 0.028107561 | BU14: ='Fee Revenue'!BV59 -> 965333.33 | BW14: =BU14/BU$8 -> 0.027677428 | BX14: ='Fee Revenue'!BY59 -> 995500 | BZ14: =BX14/BX$8 -> 0.027219161 | CA14: ='Fee Revenue'!CB59 -> 1025666.7 | CC14: =CA14/CA$8 -> 0.026801502 | CD14: ='Fee Revenue'!CE59 -> 1055833.3 | CF14: =CD14/CD$8 -> 0.026363538 | CG14: ='Fee Revenue'!CH59 -> 1086000 | CI14: =CG14/CG$8 -> 0.025861145 | CJ14: ='Fee Revenue'!CK59 -> 1116166.7 | CL14: =CJ14/CJ$8 -> 0.025395995 | CM14: ='Fee Revenue'!CN59 -> 1146333.3 | CO14: =CM14/CM$8 -> 0.024888098
B15: c. | C15: RSF - TOTAL NET FEE REVENUE | D15: =SUM(D13:D14) -> 5883166.7 | E15: n/a | F15: =D15/D$8 -> 0.48079817 | G15: =SUM(G13:G14) -> 6119666.7 | H15: =(G15-D15)/D15 -> 0.040199439 | I15: =G15/G$8 -> 0.47716699 | J15: =SUM(J13:J14) -> 5764666.7 | K15: =(J15-G15)/G15 -> -0.058009696 | L15: =J15/J$8 -> 0.4266489 | M15: =SUM(M13:M14) -> 5997666.7 | N15: =(M15-J15)/J15 -> 0.040418642 | O15: =M15/M$8 -> 0.42265365 | P15: =SUM(P13:P14) -> 6230666.7 | Q15: =(P15-M15)/M15 -> 0.038848441 | R15: =P15/P$8 -> 0.41902328 | S15: =SUM(S13:S14) -> 6411666.7 | T15: =(S15-P15)/P15 -> 0.029049861 | U15: =S15/S$8 -> 0.41439112 | V15: =SUM(V13:V14) -> 6644666.7 | W15: =(V15-S15)/S15 -> 0.036340005 | X15: =V15/V$8 -> 0.41139626 | Y15: =SUM(Y13:Y14) -> 6869333.3 | Z15: =(Y15-V15)/V15 -> 0.033811578 | AA15: =Y15/Y$8 -> 0.40631315 | AB15: =SUM(AB13:AB14) -> 7102333.3 | AC15: =(AB15-Y15)/Y15 -> 0.033918866 | AD15: =AB15/AB$8 -> 0.40185206 | AE15: =SUM(AE13:AE14) -> 7343666.7 | AF15: =(AE15-AB15)/AB15 -> 0.033979443 | AG15: =AE15/AE$8 -> 0.39830056 | AH15: =SUM(AH13:AH14) -> 7628666.7 | AI15: =(AH15-AE15)/AE15 -> 0.038808951 | AJ15: =AH15/AH$8 -> 0.39384944 | AK15: =SUM(AK13:AK14) -> 7922000 | AL15: =(AK15-AH15)/AH15 -> 0.038451455 | AM15: =AK15/AK$8 -> 0.39029437 | AN15: =SUM(AN13:AN14) -> 8155000 | AO15: =(AN15-AK15)/AK15 -> 0.029411765 | AP15: =AN15/AN$8 -> 0.3855154 | AQ15: =SUM(AQ13:AQ14) -> 8388000 | AR15: =(AQ15-AN15)/AN15 -> 0.028571429 | AS15: =AQ15/AQ$8 -> 0.3798655 | AT15: =SUM(AT13:AT14) -> 8681333.3 | AU15: =(AT15-AQ15)/AQ15 -> 0.034970593 | AV15: =AT15/AT$8 -> 0.37584784 | AW15: =SUM(AW13:AW14) -> 8966333.3 | AX15: =(AW15-AT15)/AT15 -> 0.032829059 | AY15: =AW15/AW$8 -> 0.37176165 | AZ15: =SUM(AZ13:AZ14) -> 9259666.7 | BA15: =(AZ15-AW15)/AW15 -> 0.032714971 | BB15: =AZ15/AZ$8 -> 0.36710475 | BC15: =SUM(BC13:BC14) -> 9605000 | BD15: =(BC15-AZ15)/AZ15 -> 0.037294359 | BE15: =BC15/BC$8 -> 0.36376375 | BF15: =SUM(BF13:BF14) -> 9967000 | BG15: =(BF15-BC15)/BC15 -> 0.037688704 | BH15: =BF15/BF$8 -> 0.36004696 | BI15: =SUM(BI13:BI14) -> 10312333 | BJ15: =(BI15-BF15)/BF15 -> 0.034647671 | BK15: =BI15/BI$8 -> 0.35618725 | BL15: =SUM(BL13:BL14) -> 10657667 | BM15: =(BL15-BI15)/BI15 -> 0.03348741 | BN15: =BL15/BL$8 -> 0.35162213 | BO15: =SUM(BO13:BO14) -> 11063333 | BP15: =(BO15-BL15)/BL15 -> 0.038063366 | BQ15: =BO15/BO$8 -> 0.34759204 | BR15: =SUM(BR13:BR14) -> 11417000 | BS15: =(BR15-BO15)/BO15 -> 0.03196746 | BT15: =BR15/BR$8 -> 0.34315169 | BU15: =SUM(BU13:BU14) -> 11822667 | BV15: =(BU15-BR15)/BR15 -> 0.035531809 | BW15: =BU15/BU$8 -> 0.33897204 | BX15: =SUM(BX13:BX14) -> 12228333 | BY15: =(BX15-BU15)/BU15 -> 0.03431262 | BZ15: =BX15/BX$8 -> 0.33434955 | CA15: =SUM(CA13:CA14) -> 12634000 | CB15: =(CA15-BX15)/BX15 -> 0.033174322 | CC15: =CA15/CA$8 -> 0.33013666 | CD15: =SUM(CD13:CD14) -> 13048000 | CE15: =(CD15-CA15)/CA15 -> 0.032768719 | CF15: =CD15/CD$8 -> 0.32580089 | CG15: =SUM(CG13:CG14) -> 13514000 | CH15: =(CG15-CD15)/CD15 -> 0.035714286 | CI15: =CG15/CG$8 -> 0.32181171 | CJ15: =SUM(CJ13:CJ14) -> 13928000 | CK15: =(CJ15-CG15)/CG15 -> 0.030634897 | CL15: =CJ15/CJ$8 -> 0.31690197 | CM15: =SUM(CM13:CM14) -> 14385667 | CN15: =(CM15-CJ15)/CJ15 -> 0.032859468 | CO15: =CM15/CM$8 -> 0.31232789
B17: d. | C17: New Fee Increment - Net Revenue | D17: ='Fee Revenue'!E67 -> 3097666.7 | F17: =D17/D$8 -> 0.2531549 | G17: ='Fee Revenue'!H67 -> 3266333.3 | I17: =G17/G$8 -> 0.25468486 | J17: ='Fee Revenue'!K67 -> 3435000 | L17: =J17/J$8 -> 0.25422788 | M17: ='Fee Revenue'!N67 -> 3664000 | O17: =M17/M$8 -> 0.25820091 | P17: ='Fee Revenue'!Q67 -> 3893000 | R17: =P17/P$8 -> 0.26181109 | S17: ='Fee Revenue'!T67 -> 4122000 | U17: =S17/S$8 -> 0.26640814 | V17: ='Fee Revenue'!W67 -> 4351000 | X17: =V17/V$8 -> 0.26938674 | Y17: ='Fee Revenue'!Z67 -> 4640333.3 | AA17: =Y17/Y$8 -> 0.27447037 | AB17: ='Fee Revenue'!AC67 -> 4929666.7 | AD17: =AB17/AB$8 -> 0.27892196 | AE17: ='Fee Revenue'!AF67 -> 5206666.7 | AG17: =AE17/AE$8 -> 0.28239548 | AH17: ='Fee Revenue'!AI67 -> 5556333.3 | AJ17: =AH17/AH$8 -> 0.28685993 | AK17: ='Fee Revenue'!AL67 -> 5893666.7 | AM17: =AK17/AK$8 -> 0.29036417 | AN17: ='Fee Revenue'!AO67 -> 6243333.3 | AP17: =AN17/AN$8 -> 0.29514422 | AQ17: ='Fee Revenue'!AR67 -> 6641000 | AS17: =AQ17/AQ$8 -> 0.3007495 | AT17: ='Fee Revenue'!AU67 -> 7038666.7 | AV17: =AT17/AT$8 -> 0.30473057 | AW17: ='Fee Revenue'!AX67 -> 7448666.7 | AY17: =AW17/AW$8 -> 0.30883623 | AZ17: ='Fee Revenue'!BA67 -> 7906666.7 | BB17: =AZ17/AZ$8 -> 0.3134643 | BC17: ='Fee Revenue'!BD67 -> 8364666.7 | BE17: =BC17/BC$8 -> 0.31678944 | BF17: ='Fee Revenue'!BG67 -> 8870666.7 | BH17: =BF17/BF$8 -> 0.32044312 | BI17: ='Fee Revenue'!BJ67 -> 9389000 | BK17: =BI17/BI$8 -> 0.32429539 | BL17: ='Fee Revenue'!BM67 -> 9967666.7 | BN17: =BL17/BL$8 -> 0.32885736 | BO17: ='Fee Revenue'!BP67 -> 10594333 | BQ17: =BO17/BO$8 -> 0.33285682 | BR17: ='Fee Revenue'!BS67 -> 11221000 | BT17: =BR17/BR$8 -> 0.33726068 | BU17: ='Fee Revenue'!BV67 -> 11908000 | BW17: =BU17/BU$8 -> 0.34141866 | BX17: ='Fee Revenue'!BY67 -> 12655333 | BZ17: =BX17/BX$8 -> 0.34602467 | CA17: ='Fee Revenue'!CB67 -> 13402667 | CC17: =CA17/CA$8 -> 0.35022255 | CD17: ='Fee Revenue'!CE67 -> 14198000 | CF17: =CD17/CD$8 -> 0.35451572 | CG17: ='Fee Revenue'!CH67 -> 15053667 | CI17: =CG17/CG$8 -> 0.35847611 | CJ17: ='Fee Revenue'!CK67 -> 15969667 | CL17: =CJ17/CJ$8 -> 0.36335574 | CM17: ='Fee Revenue'!CN67 -> 16946000 | CO17: =CM17/CM$8 -> 0.36791541
B19: 3 | C19: TOTAL NET FEE REVENUE (= line 1c) | D19: ='Fee Revenue'!E75 -> 8980833.3 | E19: n/a | F19: =D19/D$8 -> 0.73395308 | G19: ='Fee Revenue'!H75 -> 9386000 | H19: =(G19-D19)/D19 -> 0.045114596 | I19: =G19/G$8 -> 0.73185185 | J19: ='Fee Revenue'!K75 -> 9199666.7 | K19: =(J19-G19)/G19 -> -0.019852262 | L19: =J19/J$8 -> 0.68087678 | M19: ='Fee Revenue'!N75 -> 9661666.7 | N19: =(M19-J19)/J19 -> 0.050219211 | O19: =M19/M$8 -> 0.68085456 | P19: ='Fee Revenue'!Q75 -> 10123667 | Q19: =(P19-M19)/M19 -> 0.047817837 | R19: =P19/P$8 -> 0.68083437 | S19: ='Fee Revenue'!T75 -> 10533667 | T19: =(S19-P19)/P19 -> 0.04049916 | U19: =S19/S$8 -> 0.68079927 | V19: ='Fee Revenue'!W75 -> 10995667 | W19: =(V19-S19)/S19 -> 0.043859372 | X19: =V19/V$8 -> 0.680783 | Y19: ='Fee Revenue'!Z75 -> 11509667 | Z19: =(Y19-V19)/V19 -> 0.046745688 | AA19: =Y19/Y$8 -> 0.68078353 | AB19: ='Fee Revenue'!AC75 -> 12032000 | AC19: =(AB19-Y19)/Y19 -> 0.045382143 | AD19: =AB19/AB$8 -> 0.68077402 | AE19: ='Fee Revenue'!AF75 -> 12550333 | AF19: =(AE19-AB19)/AB19 -> 0.043079566 | AG19: =AE19/AE$8 -> 0.68069605 | AH19: ='Fee Revenue'!AI75 -> 13185000 | AI19: =(AH19-AE19)/AE19 -> 0.050569706 | AJ19: =AH19/AH$8 -> 0.68070936 | AK19: ='Fee Revenue'!AL75 -> 13815667 | AL19: =(AK19-AH19)/AH19 -> 0.047832132 | AM19: =AK19/AK$8 -> 0.68065854 | AN19: ='Fee Revenue'!AO75 -> 14398333 | AO19: =(AN19-AK19)/AK19 -> 0.042174343 | AP19: =AN19/AN$8 -> 0.68065962 | AQ19: ='Fee Revenue'!AR75 -> 15029000 | AR19: =(AQ19-AN19)/AN19 -> 0.043801366 | AS19: =AQ19/AQ$8 -> 0.68061499 | AT19: ='Fee Revenue'!AU75 -> 15720000 | AU19: =(AT19-AQ19)/AQ19 -> 0.045977776 | AV19: =AT19/AT$8 -> 0.68057841 | AW19: ='Fee Revenue'!AX75 -> 16415000 | AX19: =(AW19-AT19)/AT19 -> 0.044211196 | AY19: =AW19/AW$8 -> 0.68059788 | AZ19: ='Fee Revenue'!BA75 -> 17166333 | BA19: =(AZ19-AW19)/AW19 -> 0.045771144 | BB19: =AZ19/AZ$8 -> 0.68056905 | BC19: ='Fee Revenue'!BD75 -> 17969667 | BD19: =(BC19-AZ19)/AZ19 -> 0.046797025 | BE19: =BC19/BC$8 -> 0.68055319 | BF19: ='Fee Revenue'!BG75 -> 18837667 | BG19: =(BF19-BC19)/BC19 -> 0.048303623 | BH19: =BF19/BF$8 -> 0.68049008 | BI19: ='Fee Revenue'!BJ75 -> 19701333 | BJ19: =(BI19-BF19)/BF19 -> 0.045847858 | BK19: =BI19/BI$8 -> 0.68048264 | BL19: ='Fee Revenue'!BM75 -> 20625333 | BM19: =(BL19-BI19)/BI19 -> 0.046900379 | BN19: =BL19/BL$8 -> 0.68047949 | BO19: ='Fee Revenue'!BP75 -> 21657667 | BP19: =(BO19-BL19)/BL19 -> 0.050051716 | BQ19: =BO19/BO$8 -> 0.68044886 | BR19: ='Fee Revenue'!BS75 -> 22638000 | BS19: =(BR19-BO19)/BO19 -> 0.045264956 | BT19: =BR19/BR$8 -> 0.68041237 | BU19: ='Fee Revenue'!BV75 -> 23730667 | BV19: =(BU19-BR19)/BR19 -> 0.048266926 | BW19: =BU19/BU$8 -> 0.6803907 | BX19: ='Fee Revenue'!BY75 -> 24883667 | BY19: =(BX19-BU19)/BU19 -> 0.04858692 | BZ19: =BX19/BX$8 -> 0.68037422 | CA19: ='Fee Revenue'!CB75 -> 26036667 | CB19: =(CA19-BX19)/BX19 -> 0.046335615 | CC19: =CA19/CA$8 -> 0.68035921 | CD19: ='Fee Revenue'!CE75 -> 27246000 | CE19: =(CD19-CA19)/CA19 -> 0.046447318 | CF19: =CD19/CD$8 -> 0.68031661 | CG19: ='Fee Revenue'!CH75 -> 28567667 | CH19: =(CG19-CD19)/CD19 -> 0.04850865 | CI19: =CG19/CG$8 -> 0.68028782 | CJ19: ='Fee Revenue'!CK75 -> 29897667 | CK19: =(CJ19-CG19)/CG19 -> 0.04655613 | CL19: =CJ19/CJ$8 -> 0.68025771 | CM19: ='Fee Revenue'!CN75 -> 31331667 | CN19: =(CM19-CJ19)/CJ19 -> 0.047963609 | CO19: =CM19/CM$8 -> 0.68024331
B21: EXPENSES / OUTFLOWS
B23: 4 | C23: RSF - Existing Services
B25: a. | C25: Programs & Services supported by previous fees, net of other revenues | D25: =4862540-D28 -> 4238508 | E25: n/a | F25: =D25/D$8 -> 0.34638946 | G25: =5074208-G28 -> 4415281.9 | H25: =(G25-D25)/D25 -> 0.041706634 | I25: =G25/G$8 -> 0.34427149 | J25: =5245949-J28 -> 4574605.1 | K25: =(J25-G25)/G25 -> 0.036084495 | L25: =J25/J$8 -> 0.33857123 | M25: =5423629-M28 -> 4739494.8 | N25: =(M25-J25)/J25 -> 0.036044572 | O25: =M25/M$8 -> 0.33399068 | P25: =5607447-P28 -> 4910138.8 | Q25: =(P25-M25)/M25 -> 0.036004676 | R25: =P25/P$8 -> 0.33021546 | S25: =5801717-S28 -> 5090839.5 | T25: =(S25-P25)/P25 -> 0.036801557 | U25: =S25/S$8 -> 0.32902501 | V25: =5757663-V28 -> 5277809.2 | W25: =(V25-S25)/S25 -> 0.036726688 | X25: =V25/V$8 -> 0.32676898 | Y25: =5965506-Y28 -> 5471256.6 | Z25: =(Y25-V25)/V25 -> 0.036652971 | AA25: =Y25/Y$8 -> 0.32361852 | AB25: =6180475-AB28 -> 5671398.1 | AC25: =(AB25-Y25)/Y25 -> 0.036580539 | AD25: =AB25/AB$8 -> 0.32088933 | AE25: =6402806-AE28 -> 5878456.8 | AF25: =(AE25-AB25)/AB25 -> 0.036509286 | AG25: =AE25/AE$8 -> 0.31883156 | AH25: =6632744-AH28 -> 6092664.3 | AI25: =(AH25-AE25)/AE25 -> 0.036439415 | AJ25: =AH25/AH$8 -> 0.31454939 | AK25: =6626538-AK28 -> 6070255.9 | AL25: =(AK25-AH25)/AH25 -> -0.0036779296 | AM25: =AK25/AK$8 -> 0.29906422 | AN25: =6872449-AN28 -> 6299478.5 | AO25: =(AN25-AK25)/AK25 -> 0.037761594 | AP25: =AN25/AN$8 -> 0.2977984 | AQ25: =7126746-AQ28 -> 6536586.4 | AR25: =(AQ25-AN25)/AN25 -> 0.037639288 | AS25: =AQ25/AQ$8 -> 0.29602094 | AT25: =7389704-AT28 -> 6781839.6 | AU25: =(AT25-AQ25)/AQ25 -> 0.037520075 | AV25: =AT25/AT$8 -> 0.29361155 | AW25: =7661610-AW28 -> 7035509.6 | AX25: =(AW25-AT25)/AT25 -> 0.037404316 | AY25: =AW25/AW$8 -> 0.29170594 | AZ25: =7942759-AZ28 -> 7297875.6 | BA25: =(AZ25-AW25)/AW25 -> 0.037291682 | BB25: =AZ25/AZ$8 -> 0.28932843 | BC25: =8233454-BC28 -> 7569224.1 | BD25: =(BC25-AZ25)/AZ25 -> 0.037181848 | BE25: =BC25/BC$8 -> 0.28666417 | BF25: =8534010-BF28 -> 7849853.2 | BG25: =(BF25-BC25)/BC25 -> 0.037075016 | BH25: =BF25/BF$8 -> 0.28356735 | BI25: =8844752-BI28 -> 8140070.5 | BJ25: =(BI25-BF25)/BF25 -> 0.036971048 | BK25: =BI25/BI$8 -> 0.28115745 | BL25: =9166014-BL28 -> 8440192.1 | BM25: =(BL25-BI25)/BI25 -> 0.036869651 | BN25: =BL25/BL$8 -> 0.27846229 | BO25: =9498142-BO28 -> 8750545.4 | BP25: =(BO25-BL25)/BL25 -> 0.036770886 | BQ25: =BO25/BO$8 -> 0.27492799 | BR25: =9841492-BR28 -> 9071467.5 | BS25: =(BR25-BO25)/BO25 -> 0.036674526 | BT25: =BR25/BR$8 -> 0.27265389 | BU25: =10196432-BU28 -> 9403306.8 | BV25: =(BU25-BR25)/BR25 -> 0.036580549 | BW25: =BU25/BU$8 -> 0.26960568 | BX25: =10563343-BX28 -> 9746424 | BY25: =(BX25-BU25)/BU25 -> 0.036488998 | BZ25: =BX25/BX$8 -> 0.26648869 | CA25: =10942617-CA28 -> 10101190 | CB25: =(CA25-BX25)/BX25 -> 0.036399651 | CC25: =CA25/CA$8 -> 0.2639523 | CD25: =11334658-CD28 -> 10467989 | CE25: =(CD25-CA25)/CA25 -> 0.036312374 | CF25: =CD25/CD$8 -> 0.26137953 | CG25: =11739884-CG28 -> 10847215 | CH25: =(CG25-CD25)/CD25 -> 0.0362272 | CI25: =CG25/CG$8 -> 0.25830699 | CJ25: =12158727-CJ28 -> 11239278 | CK25: =(CJ25-CG25)/CG25 -> 0.03614411 | CL25: =CJ25/CJ$8 -> 0.25572582 | CM25: =12591631-CM28 -> 11644598 | CN25: =(CM25-CJ25)/CJ25 -> 0.036062862 | CO25: =CM25/CM$8 -> 0.25281642
B28: b. | C28: California Memorial Stadium Fitness Center | D28: 624032 | E28: n/a | F28: =D28/D$8 -> 0.050998631 | G28: =G29+G30 -> 658926.1 | H28: =(G28-D28)/D28 -> 0.055917164 | I28: =G28/G$8 -> 0.051378253 | J28: =J29+J30 -> 671343.88 | K28: =(J28-G28)/G28 -> 0.018845487 | L28: =J28/J$8 -> 0.049686851 | M28: =M29+M30 -> 684134.2 | N28: =(M28-J28)/J28 -> 0.019051811 | O28: =M28/M$8 -> 0.048210718 | P28: =P29+P30 -> 697308.23 | Q28: =(P28-M28)/M28 -> 0.019256494 | R28: =P28/P$8 -> 0.046895203 | S28: =S29+S30 -> 710877.47 | T28: =(S28-P28)/P28 -> 0.019459468 | U28: =S28/S$8 -> 0.045944577 | V28: =V29+V30 -> 479853.8 | W28: =(V28-S28)/S28 -> -0.32498382 | X28: =V28/V$8 -> 0.02970955 | Y28: =Y29+Y30 -> 494249.41 | Z28: =(Y28-V28)/V28 -> 0.03 | AA28: =Y28/Y$8 -> 0.029234283 | AB28: =AB29+AB30 -> 509076.89 | AC28: =(AB28-Y28)/Y28 -> 0.03 | AD28: =AB28/AB$8 -> 0.028803717 | AE28: =AE29+AE30 -> 524349.2 | AF28: =(AE28-AB28)/AB28 -> 0.03 | AG28: =AE28/AE$8 -> 0.028439279 | AH28: =AH29+AH30 -> 540079.68 | AI28: =(AH28-AE28)/AE28 -> 0.03 | AJ28: =AH28/AH$8 -> 0.027882995 | AK28: =AK29+AK30 -> 556282.07 | AL28: =(AK28-AH28)/AH28 -> 0.03 | AM28: =AK28/AK$8 -> 0.027406433 | AN28: =AN29+AN30 -> 572970.53 | AO28: =(AN28-AK28)/AK28 -> 0.03 | AP28: =AN28/AN$8 -> 0.027086323 | AQ28: =AQ29+AQ30 -> 590159.64 | AR28: =(AQ28-AN28)/AN28 -> 0.03 | AS28: =AQ28/AQ$8 -> 0.026726429 | AT28: =AT29+AT30 -> 607864.43 | AU28: =(AT28-AQ28)/AQ28 -> 0.03 | AV28: =AT28/AT$8 -> 0.026316756 | AW28: =AW29+AW30 -> 626100.37 | AX28: =(AW28-AT28)/AT28 -> 0.03 | AY28: =AW28/AW$8 -> 0.025959341 | AZ28: =AZ29+AZ30 -> 644883.38 | BA28: =(AZ28-AW28)/AW28 -> 0.03 | BB28: =AZ28/AZ$8 -> 0.025566768 | BC28: =BC29+BC30 -> 664229.88 | BD28: =(BC28-AZ28)/AZ28 -> 0.03 | BE28: =BC28/BC$8 -> 0.025155935 | BF28: =BF29+BF30 -> 684156.77 | BG28: =(BF28-BC28)/BC28 -> 0.03 | BH28: =BF28/BF$8 -> 0.024714414 | BI28: =BI29+BI30 -> 704681.48 | BJ28: =(BI28-BF28)/BF28 -> 0.03 | BK28: =BI28/BI$8 -> 0.024339648 | BL28: =BL29+BL30 -> 725821.92 | BM28: =(BL28-BI28)/BI28 -> 0.03 | BN28: =BL28/BL$8 -> 0.023946616 | BO28: =BO29+BO30 -> 747596.58 | BP28: =(BO28-BL28)/BL28 -> 0.03 | BQ28: =BO28/BO$8 -> 0.023488276 | BR28: =BR29+BR30 -> 770024.48 | BS28: =(BR28-BO28)/BO28 -> 0.03 | BT28: =BR28/BR$8 -> 0.023144014 | BU28: =BU29+BU30 -> 793125.21 | BV28: =(BU28-BR28)/BR28 -> 0.03 | BW28: =BU28/BU$8 -> 0.022739985 | BX28: =BX29+BX30 -> 816918.97 | BY28: =(BX28-BU28)/BU28 -> 0.03 | BZ28: =BX28/BX$8 -> 0.022336363 | CA28: =CA29+CA30 -> 841426.54 | CB28: =(CA28-BX28)/BX28 -> 0.03 | CC28: =CA28/CA$8 -> 0.021987158 | CD28: =CD29+CD30 -> 866669.33 | CE28: =(CD28-CA28)/CA28 -> 0.03 | CF28: =CD28/CD$8 -> 0.021640224 | CG28: =CG29+CG30 -> 892669.41 | CH28: =(CG28-CD28)/CD28 -> 0.03 | CI28: =CG28/CG$8 -> 0.021257323 | CJ28: =CJ29+CJ30 -> 919449.5 | CK28: =(CJ28-CG28)/CG28 -> 0.03 | CL28: =CJ28/CJ$8 -> 0.020920115 | CM28: =CM29+CM30 -> 947032.98 | CN28: =(CM28-CJ28)/CJ28 -> 0.03 | CO28: =CM28/CM$8 -> 0.020561078
C29: Operations net deficit | D29: 379032 | G29: =(D29+22838)*1.03 -> 413926.1 | J29: =G29*1.03 -> 426343.88 | M29: =J29*1.03 -> 439134.2 | P29: =M29*1.03 -> 452308.23 | S29: =P29*1.03 -> 465877.47 | V29: =S29*1.03 -> 479853.8 | Y29: =V29*1.03 -> 494249.41 | AB29: =Y29*1.03 -> 509076.89 | AE29: =AB29*1.03 -> 524349.2 | AH29: =AE29*1.03 -> 540079.68 | AK29: =AH29*1.03 -> 556282.07 | AN29: =AK29*1.03 -> 572970.53 | AQ29: =AN29*1.03 -> 590159.64 | AT29: =AQ29*1.03 -> 607864.43 | AW29: =AT29*1.03 -> 626100.37 | AZ29: =AW29*1.03 -> 644883.38 | BC29: =AZ29*1.03 -> 664229.88 | BF29: =BC29*1.03 -> 684156.77 | BI29: =BF29*1.03 -> 704681.48 | BL29: =BI29*1.03 -> 725821.92 | BO29: =BL29*1.03 -> 747596.58 | BR29: =BO29*1.03 -> 770024.48 | BU29: =BR29*1.03 -> 793125.21 | BX29: =BU29*1.03 -> 816918.97 | CA29: =BX29*1.03 -> 841426.54 | CD29: =CA29*1.03 -> 866669.33 | CG29: =CD29*1.03 -> 892669.41 | CJ29: =CG29*1.03 -> 919449.49 | CM29: =CJ29*1.03 -> 947032.98
C30: Debt service | D30: 245000 | G30: 245000 | J30: 245000 | M30: 245000 | P30: 245000 | S30: 245000 | V30: 1e-05 | Y30: 1e-05 | AB30: 1e-05 | AE30: 1e-05 | AH30: 1e-05 | AK30: 1e-05 | AN30: 1e-05 | AQ30: 1e-05 | AT30: 1e-05 | AW30: 1e-05 | AZ30: 1e-05 | BC30: 1e-05 | BF30: 1e-05 | BI30: 1e-05 | BL30: 1e-05 | BO30: 1e-05 | BR30: 1e-05 | BU30: 1e-05 | BX30: 1e-05 | CA30: 1e-05 | CD30: 1e-05 | CG30: 1e-05 | CJ30: 1e-05 | CM30: 1e-05
